Workbook

Sheet IN CONSTRUCTION
A1: STM PATTERN # | B1: DEFAULT PATTERN # | C1: EDIT_TYPE | D1: Pattern Description | E1: Expected Auditing Outcome | F1: Character Count | G1: Revised Date
A2: 1 | B2: 10001 | C2: SINGLE_LINE | D2: PROC denial due to NOT PRESENT DX | E2: Deny PROC code if DX code is not present. | F2: 41 | G2: 45763
A3: 2 | B3: 10002 | C3: SINGLE_LINE | D3: PROC denial due to NOT PRESENT MOD | E3: Deny PROC code if MOD is not present. | F3: 37 | G3: 45763
A4: 3 | B4: 10003 | C4: SINGLE_LINE | D4: PROC denial due to NOT PRESENT REV (OUTPAT_FAC) | E4: Deny PROC code if revenue code is not present. | F4: 46 | G4: 45763
A5: 4 | B5: 10004 | C5: SINGLE_LINE | D5: PROC denial due to NOT PRESENT POS | E5: Deny PROC code if POS is not present. | F5: 37 | G5: 45763
A6: 5 | B6: 10005 | C6: SINGLE_LINE | D6: PROC denial due to PRESENT AGE | E6: Deny if patient age is met. | F6: 27 | G6: 45763
A7: 6 | B7: 10006 | C7: SINGLE_LINE | D7: PROC denial due to NOT PRESENT DX and-or NOT PRESENT MOD | E7: Deny if DX code is not present and MOD is not present. | F7: 54 | G7: 45763
A8: 7 | B8: 10007 | C8: WITH_SUPPORT | D8: PROC denial due to PRESENT OTHER PROC (2-KEY D-S; SAME DOS; XPROV) | E8: Deny PROC code if present on the same DOS as the support code by any PROV. | F8: 75 | G8: 45763
A9: 8 | B9: 10008 | C9: SINGLE_LINE | D9: PROC denial due to PRESENT NON-COVERED PROC | E9: Deny PROC code when present. | F9: 28 | G9: 45763
A10: 9 | B10: 10009 | C10: SINGLE_LINE | D10: PROC denial due to NOT PRESENT DX and-or NOT PRESENT REV (OUTPAT_FAC) | E10: Deny PROC code if DX code is not present and the revenue code is not present. | F10: 77 | G10: 45763
A11: 10 | B11: 10010 | C11: WITHOUT_SUPPORT | D11: PROC denial due to NOT PRESENT OTHER PROC (1-KEY D-S; SAME DOS; XPROV) | E11: Deny PROC code if support code is not present on the same DOS by any PROV. | F11: 74 | G11: 45763
A12: 11 | B12: 10011 | C12: SINGLE_LINE | D12: PROC denial due to PRESENT DX | E12: Deny PROC code if DX code is present. | F12: 37 | G12: 0
A13: 12 | B13: 10012 | C13: SINGLE_LINE | D13: PROC denial due to PRESENT POS | E13: Deny PROC code if POS is present. | F13: 33 | G13: 45763
... A97: 96 | B97: 10096 | C97: FREQ | D97: INDIVIDUAL PROC denial due to FREQ with DENY LINE EXCL MOD- Line Quantity (SAME DOS; XPROV)(QTY=1 and ADD LINE=N) | E97: Deny if individual PROC code if qty exceeds the 1 per day limit by any PROV and the MOD is not present on the deny line. | F97: 121 | G97: 45763
A98: 97 | B98: 10097 | C98: FREQ | D98: 0 | E98: Deny individual PROC code if qty exceeds the max allowed limit within the given days range (including same DOS) by any PROV and MOD is present on current and support . | F98: 167 | G98: 45763
A99: 98 | B99: 10098 | C99: FREQ | D99: INDIVIDUAL PROC denial due to FREQ with D-S INCL MOD - Line_Quantity (SAME DOS; XPROV) (QTY=1 and ADD LINE=N) | E99: Deny individual PROC code if qty exceeds 1 per day limit by any PROV and MOD is present on current and support . | F99: 114 | G99: 45763
A100: 99 | B100: 10099 | C100: SINGLE_LINE | D100: PROC denial due to NOT PRESENT POS and/or NOT PRESENT GENDER | E100: Deny PROC code if POS and gender are not present. | F100: 50 | G100: 45763
A101: 100 | B101: 10100 | C101: SINGLE_LINE | D101: PROC denial due to NOT PRESENT POS with INCL AGE | E101: Deny PROC code when member age is met and POS is not present. | F101: 62 | G101: 45763
A102: 101 | B102: 10101 | C102: SINGLE_LINE | D102: PROC denial due to NOT PRESENT POS with INCL MOD | E102: Deny PROC code when MOD is present and POS is not present. | F102: 59 | G102: 45763
A103: 102 | B103: 10102 | C103: WITH_SUPPORT | D103: PROC denial due to PRESENT OTHER PROC (1-KEY D-S; DAYS RANGE; INCL SAME DOS, SAME PROV_FTIN) | E103: Deny PROC code if present within a given days range as the support code, by the same FTIN. | F103: 91 | G103: 0
A104: 103 | B104: 10103 | C104: FREQ | D104: PROC GROUP denial due to FREQ - Line Quantity (DAYS_RANGE, INCL SAME DOS; SAME PROV_FTIN)(QTY=1 and ADD LINE=N) | E104: Deny the PROC codes in the same subgroup, in any combination, when qty exceeds the max allowed limit within the days range (including the same DOS) by PROV with the same FTIN. | F104: 176 | G104: 0
A105: 104 | B105: 10104 | C105: SINGLE_LINE | D105: PROC denial due to INCL PRESENT POS and NOT PRESENT MODIFIER | E105: Deny PROC code when POS is present and MOD is not present. | F105: 59 | G105: 45763
A106: 105 | B106: 10105 | C106: WITHOUT_SUPPORT | D106: PROC denial due to NOT PRESENT OTHER PROC (1-KEY D-S; SAME DOS; XPROV) with INCL AGE | E106: Deny PROC code when the support code is not present on the same DOS by any PROV and member age is met. | F106: 102 | G106: 45763
A107: 106 | B107: 10106 | C107: SINGLE_LINE | D107: PROC denial due to Line_Quantity Less Than 2 or NULL | E107: Deny PROC code when the line QTY is less than 2 or is NULL. | F107: 60 | G107: 0
A108: 107 | B108: 10107 | C108: FREQ | D108: PROC GROUP denial due to FREQ - Line Quantity (DAYS_RANGE INCL SAME DOS; SAME PROV)(QTY > 1 and ADD LINE=N | E108: Deny the PROC codes in the same subgroup, in any combination, when QTY exceeds the maximum allowed within the days range (including the same DOS) by the same PROV. | F108: 164 | G108: 0
A109: 108 | B109: 10108 | C109: FREQ | D109: INDIVIDUAL PROC denial due to FREQ - Line Quantity (DAYS_RANGE; INCL SAME DOS; SAME PROV)(QTY of 1 and ADDLINE=N | E109: Deny if individual PROC code QTY exceeds the maximum allowed within the days range (including the same DOS) by the same PROV. | F109: 126 | G109: 0
A110: 109 | B110: 10109 | C110: SINGLE_LINE | D110: PROC denial due to PRESENT MOD, OR LineQuantity>1 | E110: Deny PROC code when MOD is present or when line QTY is greater than 1. | F110: 71 | G110: 0
... A173: 172 | B173: 10172 | C173: FREQ | D173: INDIVIDUAL PROC denial due to FREQ with D-S EXCL MOD- Line Quantity (SAME DOS; SAME FTIN)(QTY>1 and ADD LINE=N) | E173: Deny individual PROC code if QTY exceeds allowed amount on the same DOS by the same PROV FTIN with MOD in the category not present on both deny and support . | F173: 157 | G173: 0
A174: 173 | B174: 10173 | C174: WITH_SUPPORT | D174: PROC denial due to OTHER PRESENT PROC with INCL AGE, INCL DENY POS, INCL SUPPORT PROV SPEC, EXCL SUPPORT POS (1-KEY D-S; SAME DOS, XPROV) | E174: Deny PROC code if support code is present on same DOS by any PROV when the member age is met, POS present on deny line, PROVSPEC present on support line, and POS code not present on support line. | F174: 195 | G174: TRIM TO 200 CHARACTERS
A175: 174 | B175: 10174 | C175: SINGLE_LINE | D175: PROC denial due to NOT PRESENT REV with INCL BILL TYPE | E175: Deny PROC code when bill type is present and correct revenue code is not present. | F175: 81 | G175: 0
A176: 175 | B176: 10175 | C176: SINGLE_LINE | D176: PROC denial due to NOT PRESENT BILL TYPE and-or NOT PRESENT REV | E176: Deny PROC code when correct bill type and revenue code is not present | F176: 69 | G176: 0
A177: 176 | B177: 10176 | C177: SINGLE_LINE | D177: PROC denial due to PRESENT DX and PRESENT MOD | E177: Deny PROC code if DX and MOD is present. | F177: 40 | G177: 0
A178: 177 | B178: 10177 | C178: SINGLE_LINE | D178: PROC denial due to PRESENT AGE, PRESENT MOD, and PRESENT POS | E178: Deny PROC when member age is met, with MOD and POS is present | F178: 61 | G178: 0
A179: 178 | B179: 10178 | C179: SINGLE_LINE | D179: PROC denial due to PRESENT AGE with INCL POS | E179: Deny PROC code when POS is present and member age is met. | F179: 57 | G179: 0
A180: 179 | B180: 10179 | C180: FREQ | D180: PROC GROUP denial due to FREQ - Line Quantity (SAME DOS; SAME PROV) (QTY>1 and ADD LINE=N) | E180: Deny the PROC codes in the same subgroup, in anycombination, when the QTY exceeds the maximum allowed in the same DOS by the same PROV. | F180: 135 | G180: 0
A181: 180 | B181: 10180 | C181: WITHOUT_SUPPORT | D181: PROC denial due to NOT PRESENT OTHER PROC (2-KEY D-S; DAYS; INCL SAME DOS, XPROV) | E181: Deny PROC code if support PROC code is not present within the same DOS by any provider. | F181: 88 | G181: 46000
A182: 181 | B182: 10181 | C182: SINGLE_LINE | D182: PROC denial due to NOT PRESENT MOD with INCL MOD | E182: Deny PROC code when MOD is present and a different MOD is not present | F182: 69 | G182: 0
A183: 182 | B183: 10182 | C183: SINGLE_LINE | D183: PROC denial due to AGE with INCL GENDER | E183: Deny PROC code when member age is met and gender is present | F183: 59 | G183: 0
A184: 183 | B184: 10183 | C184: SINGLE_LINE | D184: PROV SPEC denial due to PRESENT AGE | E184: Deny PROV SPEC when member age is met | F184: 37 | G184: 0
A185: 184 | B185: 10184 | C185: FREQ | D185: INDIVIDUAL PROC denial due to FREQ - Line Quantity with INCL AGE and INCL GENDER (DAYS_RANGE; INCL SAME DOS; XPROV)(QTY=1 and ADD LINE=N) | E185: Deny PROC code if QTY exceeds the max allowed limit in a given days range (incuding the same DOS) by any provider, with patient's gender present and age is met. | F185: 161 | G185: 0
...

Sheet Master Pattern Key
A1: Team Impacted | B1: Indications | C1: Status
A2: STM | B2: All DX Codes are built with ANYDXCODES unless otherwise specified in the Pattern Description | C2: In effect
A3: DEFAULT | B3: The 50,000+ Pattern Series is to only be used by the DEFAULT/CI Team because they contain development criteria that is unique to this team such as Data Fields (Member State), Unique Keywords, and ADDLINE=Y | C3: In effect
A4: DEFAULT | B4: The 10,000+ Series is a 1:1 of a pattern (with exception of COMMON_INCLUSION) that can also be used by the STM team. | C4: In effect
A5: DEFAULT | B5: All DEFAULT patterns are created without COMMON_INCLUSION | C5: In effect
A6: DEFAULT & STM | B6: • Patterns highlighted in blue can continue to be used by the STM team. • Default Team should not be using these patterns as they still contain the COMMON_CRITERIA. | C6: In effect

Sheet Master Sheet
A1: Pattern | B1: Default Pattern | C1: Minimum PMM Version | D1: STATE | E1: Edit Type | F1: POLICY_NAME | G1: Pattern Description | H1: QRULES | I1: CLAIM_TYPE | J1: FREQ INDIV/GRP | K1: FREQ POLICY/PROC | L1: DATE SPAN | M1: SAME DAY FLAG | N1: QTY | O1: ADD LINE | P1: PROV MATCH | Q1: DX | R1: PROV TYPE | S1: MOD | T1: POS | U1: REV | V1: BILL TYPE | W1: PROV SPEC | X1: AGE | Y1: CONDITION CODE | Z1: GENDER | AA1: Admission Type | AB1: Present On Admission Indicator | AC1: NUBC (Value Code) | AD1: TOS | AE1: ECI | AF1: Billed Amount | AG1: ICD10 Proc | AH1: OCCURRENCE CODE | AI1: Taxonomy Code | AJ1: AUTH NUMBER | AK1: DISCHARGE STATUS | AL1: Member State
A2: 1 | B2: DO NOT USE | C2: 1.00 | D2: CA | E2: SINGLE_LINE | F2: DEF_CA_EYE_V2599 | G2: PROC denial due to NOT PRESENT DX | I2: PROF | J2: N/A | K2: N/A | L2: N/A | M2: N/A | N2: N/A | O2: N/A | P2: N/A | Q2: Y
A3: 2 | B3: =SUM(A3+10000) -> 10002 | C3: 1.00 | D3: NY | E3: SINGLE_LINE | F3: DEF_NY_DME_MOD | G3: PROC denial due to NOT PRESENT MOD | H3: QRULES-44349 | I3: PROF | J3: N/A | K3: N/A | L3: N/A | M3: N/A | N3: N/A | O3: N/A | P3: N/A | S3: Y
A4: 3 | B4: =SUM(A4+10000) -> 10003 | C4: 1.00 | D4: TX | E4: SINGLE_LINE | F4: DEF_TX_FETAL_NONSTRESS | G4: PROC denial due to NOT PRESENT REV (OUTPAT_FAC) | H4: QRULES-44350 | I4: OUTPAT_FAC | J4: N/A | K4: N/A | L4: N/A | M4: N/A | N4: N/A | O4: N/A | U4: Y
A5: 4 | B5: =SUM(A5+10000) -> 10004 | C5: 1.00 | D5: TX | E5: SINGLE_LINE | F5: DEF_TX_BIRTH_CRT_POS | G5: PROC denial due to NOT PRESENT POS or NULL POS | H5: QRULES-44351 | I5: PROF | J5: N/A | K5: N/A | L5: N/A | M5: N/A | N5: N/A | O5: N/A | T5: Y
A6: 5 | B6: 10005 | C6: 1.00 | D6: NY | E6: SINGLE_LINE | F6: DEF_NY_SURG_AGE1 | G6: PROC denial due to PRESENT AGE | H6: QRULES-44352 | I6: PROF | J6: N/A | K6: N/A | L6: N/A | M6: N/A | N6: N/A | O6: N/A | X6: Y
A7: 6 | B7: DO NOT USE | C7: 1.00 | D7: TX | E7: SINGLE_LINE | F7: DEF_TX_BP_DEVICE | G7: PROC denial due to NOT PRESENT DX and-or NOT PRESENT MOD | H7: QRULES-44355 | I7: PROF | J7: N/A | K7: N/A | L7: N/A | M7: N/A | N7: N/A | O7: N/A | P7: N/A | Q7: Y | S7: Y
A8: 7 | B8: =SUM(A8+10000) -> 10007 | C8: 1.00 | D8: NY | E8: WITH_SUPPORT | F8: DEF_NY_SURG_RAD1_ P2PX | G8: PROC denial due to PRESENT OTHER PROC (2-KEY D-S; SAME DOS; XPROV) | H8: QRULES-44356 | I8: PROF | J8: N/A | K8: N/A | L8: N/A | M8: Y | N8: N/A | O8: N/A | P8: Across All Prov
A9: 8 | B9: =SUM(A9+10000) -> 10008 | C9: 1.00 | D9: TX | E9: SINGLE_LINE | F9: DEF_TX_PET_SCAN | G9: PROC denial due to PRESENT NON-COVERED PROC | H9: QRULES-44357 | I9: PROF | J9: N/A | K9: N/A | L9: N/A | M9: N/A | N9: N/A | O9: N/A
A10: 9 | B10: DO NOT USE | C10: 1.00 | D10: TX | E10: SINGLE_LINE | F10: DEF_TX_CARDIAC_REHAB | G10: PROC denial due to NOT PRESENT DX and-or NOT PRESENT REV (OUTPAT_FAC) | H10: QRULES-44358 | I10: OUTPAT_FAC | J10: N/A | K10: N/A | L10: N/A | M10: N/A | N10: N/A | O10: N/A | P10: N/A | Q10: Y | U10: Y
A11: 10 | B11: =SUM(A11+10000) -> 10010 | C11: 1.00 | D11: CA | E11: WITHOUT_SUPPORT | F11: DEF_CA_INFUSION_BACLOFEN | G11: PROC denial due to NOT PRESENT OTHER PROC (1-KEY D-S; SAME DOS; XPROV) | H11: QRULES-44359 | I11: PROF | J11: N/A | K11: N/A | L11: N/A | M11: Y | N11: N/A | O11: N/A | P11: Across All Prov
A12: 11 | B12: DO NOT USE | C12: 1.00 | D12: CA | E12: SINGLE_LINE | F12: DEF_CA_FROZEN_PLASMA | G12: PROC denial due to PRESENT DX | H12: QRULES-44363 | I12: PROF | J12: N/A | K12: N/A | L12: N/A | M12: N/A | N12: N/A | O12: N/A | P12: N/A | Q12: Y
A13: 12 | B13: =SUM(A13+10000) -> 10012 | C13: 1.00 | D13: TX | E13: SINGLE_LINE | F13: DEF_TX_ESRD_DIALYSIS_NOT_HOME | G13: PROC denial due to PRESENT POS | H13: QRULES-44389 | I13: PROF | J13: N/A | K13: N/A | L13: N/A | M13: N/A | N13: N/A | O13: N/A | T13: Y
A14: 13 | B14: =SUM(A14+10000) -> 10013 | C14: 2.00 | D14: CA | E14: FREQ | F14: DEF_CA_DME_ONCE_IN_5YRS | G14: INDIVIDUAL PROC denial due to FREQ - Line Quantity (DAYS_RANGE; INCL SAME DOS; XPROV)(QTY=1 and ADD LINE=N) | H14: QRULES-44388 | I14: PROF | J14: INDIV | K14: POLICY | L14: DAYS_RANGE | M14: Y | N14: =1 -> 1 | O14: N | P14: Across All Prov
A15: 14 | B15: =SUM(A15+10000) -> 10014 | C15: 1.00 | D15: CA | E15: SINGLE_LINE | F15: DEF_CA_MED_NO_MOD_63 | G15: PROC denial due to PRESENT MOD | H15: QRULES-44390 | I15: PROF | J15: N/A | K15: N/A | L15: N/A | M15: N/A | N15: N/A | O15: N/A | P15: N/A | S15: Y
A16: 15 | B16: =SUM(A16+10000) -> 10015 | C16: 1.00 | D16: CA | E16: WITH_SUPPORT | F16: DEF_CA_DME_RENT_SAME_MONTH | G16: PROC denial due to PRESENT OTHER PROC (1-KEY D-S; CALENDAR_MONTH; INCL SAME DOS; XPROV) | H16: QRULES-44391 | I16: PROF | J16: N/A | K16: N/A | L16: CALENDAR_MONTH | M16: Y | N16: N/A | O16: N/A | P16: Across All Prov
A17: 16 | B17: =SUM(A17+10000) -> 10016 | C17: 2.00 | D17: N/A | E17: COMBO | F17: (Patterns 13 + 19) | G17: COMBINATION (Patterns 13 + 19) | H17: QRULES-44461 | I17: PROF | J17: N/A | K17: N/A | L17: N/A | M17: N/A | N17: N/A | O17: N/A | P17: N/A
A18: 17 | B18: =SUM(A18+10000) -> 10017 | C18: 2.00 | D18: N/A | E18: COMBO | F18: (Patterns 20 + 25) | G18: COMBINATION (Patterns 20 + 25) | H18: QRULES-44462 | I18: PROF | J18: N/A | K18: N/A | L18: N/A | M18: N/A | N18: N/A | O18: N/A | P18: N/A
A19: 18 | B19: =SUM(A19+10000) -> 10018 | C19: 2.00 | D19: N/A | E19: COMBO | F19: (Patterns 21 + 13) | G19: COMBINATION (Patterns 21 + 13) | H19: QRULES-45025 | I19: PROF | J19: N/A | K19: N/A | L19: N/A | M19: N/A | N19: N/A | O19: N/A | P19: N/A
A20: 19 | B20: =SUM(A20+10000) -> 10019 | C20: 1.00 | D20: NY | E20: FREQ | F20: DEF_NY_LAB_SVCS_1 | G20: INDIVIDUAL PROC denial due to FREQ - Line Quantity (SAME DOS; XPROV)(QTY=1 and ADD LINE=N) | H20: QRULES-44463 | I20: PROF | J20: INDIV | K20: POLICY | L20: N/A | M20: Y | N20: =1 -> 1 | O20: N | P20: Across All Prov
A21: 20 | B21: =SUM(A21+10000) -> 10020 | C21: 1.00 | D21: CA | E21: FREQ | F21: DEF_CA_PDT_FREQ_1 | G21: INDIVIDUAL PROC denial due to FREQ - Line Quantity (SAME DOS; SAME PROV)(QTY=1 and ADD LINE=N) | H21: QRULES-44464 | I21: PROF | J21: INDIV | K21: POLICY | L21: N/A | M21: Y | N21: =1 -> 1 | O21: N | P21: PROV_ID
A22: 21 | B22: =SUM(A22+10000) -> 10021 | C22: 1.00 | D22: TX | E22: SINGLE_LINE | F22: DEF_TX_RAD_URICHEM_MALE_1 | G22: PROC denial due to NOT PRESENT GENDER M | H22: QRULES-45026 | I22: PROF | J22: N/A | K22: N/A | L22: N/A | M22: N/A | N22: N/A | O22: N/A | Z22: Y
A23: 22 | B23: =SUM(A23+10000) -> 10022 | C23: 1.00 | D23: CA | E23: SINGLE_LINE | F23: DEF_CA_DME_MODNURB | G23: PROC denial due to NOT PRESENT MOD1, AND/OR NOT PRESENT MOD2 | H23: QRULES-45032 | I23: PROF | J23: N/A | K23: N/A | L23: N/A | M23: N/A | N23: N/A | O23: N/A | P23: N/A | S23: Y
A24: 23 | B24: =SUM(A24+10000) -> 10023 | C24: 1.00 | D24: CA | E24: FREQ | F24: DEF_CA_RADSURG_FREQ | G24: PROC GROUP denial due to FREQ - Line Quantity (DAYS_RANGE, INCL SAME DOS; XPROV)(QTY>1 and ADD LINE=N) | H24: QRULES-45033 | I24: PROF | J24: GRP | K24: POLICY | L24: DAYS_RANGE | M24: Y | N24: >1 | O24: N | P24: Across All Prov
A25: 24 | B25: =SUM(A25+10000) -> 10024 | C25: 1.00 | D25: TX | E25: SINGLE_LINE | F25: DEF_TX_INPT_ADMIT_DAY_SURG | G25: PROC denial due to NOT PRESENT Claim_PrincipalDiag and-or NOT PRESENT BILL TYPE (ALL_FAC) | H25: QRULES-45046 | I25: ALL_FAC | J25: N/A | K25: N/A | L25: N/A | M25: N/A | N25: N/A | O25: N/A | P25: N/A | Q25: Y | V25: Y
A26: 25 | B26: =SUM(A26+10000) -> 10025 | C26: 2.00 | D26: CA | E26: FREQ | F26: DEF_CA_PDT_FREQ_2 | G26: INDIVIDUAL PROC denial due to FREQ - Line Quantity (DAYS_RANGE; INCL SAME DOS; SAME PROV)(QTY>1 and ADD LINE=N) | H26: QRULES-45067 | I26: PROF | J26: INDIV | K26: POLICY | L26: DAYS_RANGE | M26: Y | N26: >1 | O26: N | P26: PROV_ID
A27: 26 | B27: DO NOT USE | C27: 1.00 | D27: TX | E27: SINGLE_LINE | F27: DEF_TX_CRANIAL_DOPPLR_AGE_1 | G27: PROC denial due to PRESENT AGE with INCL DX | H27: QRULES-45077 | I27: PROF | J27: N/A | K27: N/A | L27: N/A | M27: N/A | N27: N/A | O27: N/A | P27: N/A | Q27: Y | X27: Y
A28: 27 | B28: DO NOT USE | C28: 2.00 | D28: TX | E28: FREQ | F28: DEF_TX_CRANIAL_DOPPLR_AGE_2 | G28: INDIVIDUAL PROC denial due to FREQ with D-S INCL DX - Line Quantity (DAYS_RANGE; INCL SAME DOS; XPROV)(QTY=1 and ADD LINE=N) | H28: QRULES-45078 | I28: PROF | J28: INDIV | K28: POLICY | L28: DAYS_RANGE | M28: Y | N28: 1 | O28: N | P28: Across All Prov | Q28: Y
A29: 28 | B29: =SUM(A29+10000) -> 10028 | C29: 2.00 | D29: N/A | E29: COMBO | F29: (Patterns 26 + 27) | G29: COMBINATION (Patterns 26 + 27) | H29: QRULES-45079 | I29: PROF | J29: N/A | K29: N/A | L29: DAYS_RANGE | M29: Y | N29: N/A | O29: N/A | P29: N/A
A30: 29 | B30: =SUM(A30+10000) -> 10029 | C30: 2.00 | D30: TX | E30: FREQ | F30: DEF_CA_MRI_EWC | G30: INDIVIDUAL PROC denial due to FREQ - Line Quantity (DAYS_RANGE; INCL SAME DOS; XPROV)(QTY>1 and ADD LINE=N) | H30: QRULES-45092 | I30: PROF | J30: INDIV | K30: POLICY | L30: DAYS_RANGE | M30: Y | N30: >1 | O30: N | P30: Across All Prov
A31: 30 | B31: =SUM(A31+10000) -> 10030 | C31: 2.00 | D31: N/A | E31: COMBO | F31: (Patterns 5 + 29) | G31: COMBINATION (Patterns 5 + 29) | H31: QRULES-45093 | I31: PROF | J31: N/A | K31: N/A | L31: DAYS_RANGE | M31: Y | N31: N/A | O31: N/A | P31: N/A
A32: 31 | B32: =SUM(A32+10000) -> 10031 | C32: 1.00 | D32: TX | E32: SINGLE_LINE | F32: DEF_TX_FOBT_FREQ_1 | G32: PROC denial due to PRESENT AGE with INCL MOD | H32: QRULES-45094 | I32: PROF | J32: N/A | K32: N/A | L32: N/A | M32: N/A | N32: N/A | O32: N/A | P32: N/A | S32: Y | X32: Y
A33: 32 | B33: =SUM(A33+10000) -> 10032 | C33: 2.00 | D33: TX | E33: FREQ | F33: DEF_TX_FOBT_FREQ_2 | G33: INDIVIDUAL PROC denial due to FREQ with DENY MOD INCL - Line Quantity (DAYS_RANGE; INCL SAME DOS; XPROV)(QTY=1 and ADD LINE=N) | H33: QRULES-45095 | I33: PROF | J33: INDIV | K33: POLICY | L33: DAYS_RANGE | M33: Y | N33: 1 | O33: N | P33: Across All Prov | S33: Y
A34: 33 | B34: =SUM(A34+10000) -> 10033 | C34: 2.00 | D34: N/A | E34: COMBO | F34: (Patterns 31 + 32) | G34: COMBINATION (Patterns 31 + 32) | H34: QRULES-45096 | I34: PROF | J34: N/A | K34: N/A | L34: DAYS_RANGE | M34: N/A | N34: N/A | O34: N/A | P34: N/A
A35: 34 | B35: =SUM(A35+10000) -> 10034 | C35: 1.00 | D35: TX | E35: WITH_SUPPORT | F35: DEF_TX_MAMMO_NO_GG | G35: PROC denial due to PRESENT OTHER PROC with SUPPORT EXCL MOD (1-KEY D-S; SAME DOS; XPROV) | H35: QRULES-45104 | I35: PROF | J35: N/A | K35: N/A | L35: N/A | M35: Y | N35: N/A | O35: N/A | P35: Across All Prov | S35: Y
A36: 35 | B36: =SUM(A36+10000) -> 10035 | C36: 1.00 | D36: CA | E36: WITH_SUPPORT | F36: DEF_CA_DME_WALKER_1 | G36: PROC denial due to PRESENT OTHER PROC with SUPPORT MOD INCL (1-KEY ; SAME DOS; XPROV) | H36: QRULES-45105 | I36: PROF | J36: N/A | K36: N/A | L36: N/A | M36: Y | N36: N/A | O36: N/A | P36: Across All Prov | S36: Y
A37: 36 | B37: =SUM(A37+10000) -> 10036 | C37: 2.00 | D37: N/A | E37: COMBO | F37: (Patterns 35 + 29) | G37: COMBINATION (Patterns 35 + 29) | H37: QRULES-45106 | I37: PROF | J37: N/A | K37: N/A | L37: N/A | M37: N/A | N37: N/A | O37: N/A | P37: N/A
A38: 37 | B38: =SUM(A38+10000) -> 10037 | C38: 1.00 | D38: CA | E38: SINGLE_LINE | F38: DEF_CA_LOWVISION | G38: PROC denial due to Line_Quantity >1, AND/OR NOT PRESENT MOD | H38: QRULES-45134 | I38: PROF | J38: N/A | K38: N/A | L38: N/A | M38: N/A | N38: N/A | O38: N/A | P38: N/A | S38: Y
A39: 38 | B39: =SUM(A39+10000) -> 10038 | C39: 1.00 | D39: CA | E39: FREQ | F39: DEF_CA_MED_NVDS_2 | G39: PROC GROUP denial due to FREQ - Line Quantity (SAME DOS; SAME PROV)(QTY=1 and ADD LINE=N) | H39: QRULES-45135 | I39: PROF | J39: GRP | K39: POLICY | L39: N/A | M39: Y | N39: 1 | O39: N | P39: PROV_ID
A40: 39 | B40: =SUM(A40+10000) -> 10039 | C40: 1.00 | D40: N/A | E40: COMBO | F40: (Patterns 14 + 38) | G40: COMBINATION (Patterns 14 + 38) | H40: QRULES-45136 | I40: PROF | J40: N/A | K40: N/A | L40: N/A | M40: N/A | N40: N/A | O40: N/A | P40: N/A
...

Sheet Expected Auditing Outcomes
B1: STM PATTERN # | C1: DEFAULT Pattern # | D1: EDIT TYPE | E1: PATTERN DESCRIPTION | F1: Expected Auditing Outcome | G1: Characters | H1: Revised Date
B2: Deny individual PROC code when QTY exceeds max allowed limit on the same DOS, by any PROV, with PROV TYPE and POS present on deny and support, and two distinct MODIFIERS are present on both deny and support line | C2: =SUM($B2+10000) -> #VALUE! | D2: SINGLE_LINE | E2: PROC denial due to NOT PRESENT DX | F2: Deny PROC code if DX code is not present. | G2: =LEN('Expected Auditing Outcomes'!$F2) -> 41 | H2: 45763
B3: 2 | C3: =SUM($B3+10000) -> 10002 | D3: SINGLE_LINE | E3: =VLOOKUP('Expected Auditing Outcomes'!$B3,'Master Sheet'!A3:G1032, 7, FALSE) -> PROC denial due to NOT PRESENT MOD | F3: Deny PROC code if MOD is not present. | G3: =LEN('Expected Auditing Outcomes'!$F3) -> 37 | H3: 45763
B4: 3 | C4: =SUM($B4+10000) -> 10003 | D4: SINGLE_LINE | E4: =VLOOKUP('Expected Auditing Outcomes'!$B4,'Master Sheet'!A4:G1033, 7, FALSE) -> PROC denial due to NOT PRESENT REV (OUTPAT_FAC) | F4: Deny PROC code if revenue code is not present. | G4: =LEN('Expected Auditing Outcomes'!$F4) -> 46 | H4: 45763
B5: 4 | C5: =SUM($B5+10000) -> 10004 | D5: SINGLE_LINE | E5: =VLOOKUP('Expected Auditing Outcomes'!$B5,'Master Sheet'!A5:G1034, 7, FALSE) -> PROC denial due to NOT PRESENT POS or NULL POS | F5: Deny PROC code if POS is not present. | G5: =LEN('Expected Auditing Outcomes'!$F5) -> 37 | H5: 45763
B6: 5 | C6: =SUM($B6+10000) -> 10005 | D6: SINGLE_LINE | E6: PROC denial due to PRESENT AGE | F6: Deny if patient age is met. | G6: =LEN('Expected Auditing Outcomes'!$F6) -> 27 | H6: 45763
B7: 6 | C7: =SUM($B7+10000) -> 10006 | D7: SINGLE_LINE | E7: =VLOOKUP('Expected Auditing Outcomes'!$B7,'Master Sheet'!A7:G1036, 7, FALSE) -> PROC denial due to NOT PRESENT DX and-or NOT PRESENT MOD | F7: Deny PROC code if DX code is not present and MOD is not present. | G7: =LEN('Expected Auditing Outcomes'!$F7) -> 64 | H7: 45763
B8: 7 | C8: =SUM($B8+10000) -> 10007 | D8: WITH_SUPPORT | E8: =VLOOKUP('Expected Auditing Outcomes'!$B8,'Master Sheet'!A8:G1037, 7, FALSE) -> PROC denial due to PRESENT OTHER PROC (2-KEY D-S; SAME DOS; XPROV) | F8: Deny PROC code if present on the same DOS as the support code by any PROV. | G8: =LEN('Expected Auditing Outcomes'!$F8) -> 75 | H8: 45763
B9: 8 | C9: =SUM($B9+10000) -> 10008 | D9: SINGLE_LINE | E9: PROC denial due to PRESENT NON-COVERED PROC | F9: Deny PROC code when present. | G9: =LEN('Expected Auditing Outcomes'!$F9) -> 28 | H9: 45763
B10: 9 | C10: =SUM($B10+10000) -> 10009 | D10: SINGLE_LINE | E10: =VLOOKUP('Expected Auditing Outcomes'!$B10,'Master Sheet'!A10:G1039, 7, FALSE) -> PROC denial due to NOT PRESENT DX and-or NOT PRESENT REV (OUTPAT_FAC) | F10: Deny PROC code if DX code is not present and the revenue code is not present. | G10: =LEN('Expected Auditing Outcomes'!$F10) -> 77 | H10: 45763
B11: 10 | C11: =SUM($B11+10000) -> 10010 | D11: WITHOUT_SUPPORT | E11: PROC denial due to NOT PRESENT OTHER PROC (1-KEY D-S; SAME DOS; XPROV) | F11: Deny PROC code if support code is not present on the same DOS by any PROV. | G11: =LEN('Expected Auditing Outcomes'!$F11) -> 74 | H11: 45763
B12: 11 | C12: =SUM($B12+10000) -> 10011 | D12: SINGLE_LINE | E12: =VLOOKUP('Expected Auditing Outcomes'!$B12,'Master Sheet'!A12:G1051, 7, FALSE) -> PROC denial due to PRESENT DX | F12: Deny PROC code if DX code is present. | G12: =LEN('Expected Auditing Outcomes'!$F12) -> 37
B13: 12 | C13: =SUM($B13+10000) -> 10012 | D13: SINGLE_LINE | E13: =VLOOKUP('Expected Auditing Outcomes'!$B13,'Master Sheet'!A13:G1051, 7, FALSE) -> PROC denial due to PRESENT POS | F13: Deny PROC code if POS is present. | G13: =LEN('Expected Auditing Outcomes'!$F13) -> 33 | H13: 45763
B14: 13 | C14: =SUM($B14+10000) -> 10013 | D14: FREQ | E14: =VLOOKUP('Expected Auditing Outcomes'!$B14,'Master Sheet'!A14:G1051, 7, FALSE) -> INDIVIDUAL PROC denial due to FREQ - Line Quantity (DAYS_RANGE; INCL SAME DOS; XPROV)(QTY=1 and ADD LINE=N) | F14: Deny if PROC code qty exceeds the max allowed limit within the given days range (including the same DOS) by any PROV. | G14: =LEN('Expected Auditing Outcomes'!$F14) -> 117 | H14: 45763
B15: 14 | C15: =SUM($B15+10000) -> 10014 | D15: SINGLE_LINE | E15: =VLOOKUP('Expected Auditing Outcomes'!$B15,'Master Sheet'!A15:G1051, 7, FALSE) -> PROC denial due to PRESENT MOD | F15: Deny PROC code if MOD is present. | G15: =LEN('Expected Auditing Outcomes'!$F15) -> 33 | H15: 45763
B16: 15 | C16: =SUM($B16+10000) -> 10015 | D16: WITH_SUPPORT | E16: =VLOOKUP('Expected Auditing Outcomes'!$B16,'Master Sheet'!A16:G1051, 7, FALSE) -> PROC denial due to PRESENT OTHER PROC (1-KEY D-S; CALENDAR_MONTH; INCL SAME DOS; XPROV) | F16: Deny PROC code if present within the same calendar month as the support code (including the same DOS) by any PROV. | G16: =LEN('Expected Auditing Outcomes'!$F16) -> 115 | H16: 45763
B17: 16 | C17: =SUM($B17+10000) -> 10016 | D17: COMBO | E17: =VLOOKUP('Expected Auditing Outcomes'!$B17,'Master Sheet'!A17:G1051, 7, FALSE) -> COMBINATION (Patterns 13 + 19) | F17: Each policy should have the expected auditing outcome connected to the indivual pattern identified for that policy. | G17: =LEN('Expected Auditing Outcomes'!$F17) -> 115
B18: 17 | C18: =SUM($B18+10000) -> 10017 | D18: COMBO | E18: =VLOOKUP('Expected Auditing Outcomes'!$B18,'Master Sheet'!A18:G1051, 7, FALSE) -> COMBINATION (Patterns 20 + 25) | F18: Each policy should have the expected auditing outcome connected to the indivual pattern identified for that policy. | G18: =LEN('Expected Auditing Outcomes'!$F18) -> 115
B19: 18 | C19: =SUM($B19+10000) -> 10018 | D19: COMBO | E19: =VLOOKUP('Expected Auditing Outcomes'!$B19,'Master Sheet'!A19:G1051, 7, FALSE) -> COMBINATION (Patterns 21 + 13) | F19: Each policy should have the expected auditing outcome connected to the indivual pattern identified for that policy. | G19: =LEN('Expected Auditing Outcomes'!$F19) -> 115
B20: 19 | C20: =SUM($B20+10000) -> 10019 | D20: FREQ | E20: =VLOOKUP('Expected Auditing Outcomes'!$B20,'Master Sheet'!A20:G1051, 7, FALSE) -> INDIVIDUAL PROC denial due to FREQ - Line Quantity (SAME DOS; XPROV)(QTY=1 and ADD LINE=N) | F20: Deny PROC code if qty exceeds the max allowed limit on the same DOS by any PROV. | G20: =LEN('Expected Auditing Outcomes'!$F20) -> 80 | H20: 45763
B21: 20 | C21: =SUM($B21+10000) -> 10020 | D21: FREQ | E21: =VLOOKUP('Expected Auditing Outcomes'!$B21,'Master Sheet'!A21:G1051, 7, FALSE) -> INDIVIDUAL PROC denial due to FREQ - Line Quantity (SAME DOS; SAME PROV)(QTY=1 and ADD LINE=N) | F21: Deny PROC code if qty exceeds the max allowed limit on the same day by the same PROV. | G21: =LEN('Expected Auditing Outcomes'!$F21) -> 86 | H21: 45763
B22: 21 | C22: =SUM($B22+10000) -> 10021 | D22: SINGLE_LINE | E22: =VLOOKUP('Expected Auditing Outcomes'!$B22,'Master Sheet'!A22:G1051, 7, FALSE) -> PROC denial due to NOT PRESENT GENDER M | F22: Deny PROC code when specific gender value is not present. | G22: =LEN('Expected Auditing Outcomes'!$F22) -> 57 | H22: 45763
B23: 22 | C23: =SUM($B23+10000) -> 10022 | D23: SINGLE_LINE | E23: =VLOOKUP('Expected Auditing Outcomes'!$B23,'Master Sheet'!A23:G1051, 7, FALSE) -> PROC denial due to NOT PRESENT MOD1, AND/OR NOT PRESENT MOD2 | F23: Deny PROC code if two distinct MODs are not present on any of the MOD positions. | G23: =LEN('Expected Auditing Outcomes'!$F23) -> 80 | H23: 45763
B24: 23 | C24: =SUM($B24+10000) -> 10023 | D24: FREQ | E24: =VLOOKUP('Expected Auditing Outcomes'!$B24,'Master Sheet'!A24:G1051, 7, FALSE) -> PROC GROUP denial due to FREQ - Line Quantity (DAYS_RANGE, INCL SAME DOS; XPROV)(QTY>1 and ADD LINE=N) | F24: Deny the PROC codes in the same subgroup, in any combination, when qty exceeds the max allowed limit within the days range (including the same DOS) by any PROV. | G24: =LEN('Expected Auditing Outcomes'!$F24) -> 160 | H24: 45763
B25: 24 | C25: =SUM($B25+10000) -> 10024 | D25: SINGLE_LINE | E25: =VLOOKUP('Expected Auditing Outcomes'!$B25,'Master Sheet'!A25:G1051, 7, FALSE) -> PROC denial due to NOT PRESENT Claim_PrincipalDiag and-or NOT PRESENT BILL TYPE (ALL_FAC) | F25: Deny PROC code if Claim Principal DX is not present or if correct bill type is not present. | G25: =LEN('Expected Auditing Outcomes'!$F25) -> 92 | H25: 45763
B26: 25 | C26: =SUM($B26+10000) -> 10025 | D26: FREQ | E26: =VLOOKUP('Expected Auditing Outcomes'!$B26,'Master Sheet'!A26:G1051, 7, FALSE) -> INDIVIDUAL PROC denial due to FREQ - Line Quantity (DAYS_RANGE; INCL SAME DOS; SAME PROV)(QTY>1 and ADD LINE=N) | F26: Deny PROC code if qty exceeds the max allowed limit within the given days range (including the same DOS) by the same PROV. | G26: =LEN('Expected Auditing Outcomes'!$F26) -> 123 | H26: 45763
B27: 26 | C27: =SUM($B27+10000) -> 10026 | D27: SINGLE_LINE | E27: =VLOOKUP('Expected Auditing Outcomes'!$B27,'Master Sheet'!A27:G1051, 7, FALSE) -> PROC denial due to PRESENT AGE with INCL DX | F27: Deny PROC code if age criteria is met and DX is present. | G27: =LEN('Expected Auditing Outcomes'!$F27) -> 57 | H27: 45763
B28: 27 | C28: =SUM($B28+10000) -> 10027 | D28: FREQ | E28: =VLOOKUP('Expected Auditing Outcomes'!$B28,'Master Sheet'!A28:G1051, 7, FALSE) -> INDIVIDUAL PROC denial due to FREQ with D-S INCL DX - Line Quantity (DAYS_RANGE; INCL SAME DOS; XPROV)(QTY=1 and ADD LINE=N) | F28: Deny PROC code if qty exceeds the max allowed limit within the given days range (including the same DOS) by any PROV and DX is present on deny and support line | G28: =LEN('Expected Auditing Outcomes'!$F28) -> 159 | H28: 45763
B29: 28 | C29: =SUM($B29+10000) -> 10028 | D29: COMBO | E29: =VLOOKUP('Expected Auditing Outcomes'!$B29,'Master Sheet'!A29:G1051, 7, FALSE) -> COMBINATION (Patterns 26 + 27) | F29: Each policy should have the expected auditing outcome connected to the indivual pattern identified for that policy. | G29: =LEN('Expected Auditing Outcomes'!$F29) -> 115
B30: 29 | C30: =SUM($B30+10000) -> 10029 | D30: FREQ | E30: =VLOOKUP('Expected Auditing Outcomes'!$B30,'Master Sheet'!A30:G1051, 7, FALSE) -> INDIVIDUAL PROC denial due to FREQ - Line Quantity (DAYS_RANGE; INCL SAME DOS; XPROV)(QTY>1 and ADD LINE=N) | F30: Deny PROC code if qty exceeds the max allowed limit within the given days range (including the same DOS) by any PROV. | G30: =LEN('Expected Auditing Outcomes'!$F30) -> 117 | H30: 45763
B31: 30 | C31: =SUM($B31+10000) -> 10030 | D31: COMBO | E31: =VLOOKUP('Expected Auditing Outcomes'!$B31,'Master Sheet'!A31:G1051, 7, FALSE) -> COMBINATION (Patterns 5 + 29) | F31: Each policy should have the expected auditing outcome connected to the indivual pattern identified for that policy. | G31: =LEN('Expected Auditing Outcomes'!$F31) -> 115
B32: 31 | C32: =SUM($B32+10000) -> 10031 | D32: SINGLE_LINE | E32: =VLOOKUP('Expected Auditing Outcomes'!$B32,'Master Sheet'!A32:G1051, 7, FALSE) -> PROC denial due to PRESENT AGE with INCL MOD | F32: Deny PROC code if age criteria is met and MOD is present. | G32: =LEN('Expected Auditing Outcomes'!$F32) -> 58 | H32: 45763
B33: 32 | C33: =SUM($B33+10000) -> 10032 | D33: FREQ | E33: =VLOOKUP('Expected Auditing Outcomes'!$B33,'Master Sheet'!A33:G1051, 7, FALSE) -> INDIVIDUAL PROC denial due to FREQ with DENY MOD INCL - Line Quantity (DAYS_RANGE; INCL SAME DOS; XPROV)(QTY=1 and ADD LINE=N) | F33: Deny PROC code if qty exceeds the max allowed limit within the given days range (including the same DOS) by any PROV and MOD is present on deny line. | G33: =LEN('Expected Auditing Outcomes'!$F33) -> 150 | H33: 45763
B34: 33 | C34: =SUM($B34+10000) -> 10033 | D34: COMBO | E34: =VLOOKUP('Expected Auditing Outcomes'!$B34,'Master Sheet'!A34:G1051, 7, FALSE) -> COMBINATION (Patterns 31 + 32) | F34: Each policy should have the expected auditing outcome connected to the indivual pattern identified for that policy. | G34: =LEN('Expected Auditing Outcomes'!$F34) -> 115
B35: 34 | C35: =SUM($B35+10000) -> 10034 | D35: WITH_SUPPORT | E35: =VLOOKUP('Expected Auditing Outcomes'!$B35,'Master Sheet'!A35:G1051, 7, FALSE) -> PROC denial due to PRESENT OTHER PROC with SUPPORT EXCL MOD (1-KEY D-S; SAME DOS; XPROV) | F35: Deny PROC code when support code is present on the same day by any PROV and MOD is NOT PRESENT on support line | G35: =LEN('Expected Auditing Outcomes'!$F35) -> 110 | H35: 45763
B36: 35 | C36: =SUM($B36+10000) -> 10035 | D36: WITH_SUPPORT | E36: =VLOOKUP('Expected Auditing Outcomes'!$B36,'Master Sheet'!A36:G1051, 7, FALSE) -> PROC denial due to PRESENT OTHER PROC with SUPPORT MOD INCL (1-KEY ; SAME DOS; XPROV) | F36: Deny PROC code when support code is present on the same day by any PROV and MOD is present on support line. | G36: =LEN('Expected Auditing Outcomes'!$F36) -> 107 | H36: 45763
B37: 36 | C37: =SUM($B37+10000) -> 10036 | D37: COMBO | E37: =VLOOKUP('Expected Auditing Outcomes'!$B37,'Master Sheet'!A37:G1051, 7, FALSE) -> COMBINATION (Patterns 35 + 29) | F37: Each policy should have the expected auditing outcome connected to the indivual pattern identified for that policy. | G37: =LEN('Expected Auditing Outcomes'!$F37) -> 115
B38: 37 | C38: =SUM($B38+10000) -> 10037 | D38: SINGLE_LINE | E38: =VLOOKUP('Expected Auditing Outcomes'!$B38,'Master Sheet'!A38:G1051, 7, FALSE) -> PROC denial due to Line_Quantity >1, AND/OR NOT PRESENT MOD | F38: Deny if PROC code if line qty is greater than 1 or correct MOD is not present. | G38: =LEN('Expected Auditing Outcomes'!$F38) -> 78 | H38: 45763
B39: 38 | C39: =SUM($B39+10000) -> 10038 | D39: FREQ | E39: =VLOOKUP('Expected Auditing Outcomes'!$B39,'Master Sheet'!A39:G1051, 7, FALSE) -> PROC GROUP denial due to FREQ - Line Quantity (SAME DOS; SAME PROV)(QTY=1 and ADD LINE=N) | F39: Deny the PROC codes in the same subgroup, in any combination, when qty exceeds the max allowed limit on the same day by the same PROV. | G39: =LEN('Expected Auditing Outcomes'!$F39) -> 135 | H39: 45763
B40: 39 | C40: =SUM($B40+10000) -> 10039 | D40: COMBO | E40: =VLOOKUP('Expected Auditing Outcomes'!$B40,'Master Sheet'!A40:G1051, 7, FALSE) -> COMBINATION (Patterns 14 + 38) | F40: Each policy should have the expected auditing outcome connected to the indivual pattern identified for that policy. | G40: =LEN('Expected Auditing Outcomes'!$F40) -> 115
...

Sheet Removed Pattern Rationale
A1: Pattern | B1: Rationale | C1: Impacted Framework
A2: 13 | B2: Pattern Crosswalked due to defect with PMM including support lines prior and after proc code effective dates. | C2: 1
A3: 16 | B3: Pattern Crosswalked due to defect with PMM including support lines prior and after proc code effective dates. | C3: 1
A4: 17 | B4: Pattern Crosswalked due to defect with PMM including support lines prior and after proc code effective dates. | C4: 1
A5: 18 | B5: Pattern Crosswalked due to defect with PMM including support lines prior and after proc code effective dates. | C5: 1
A6: 25 | B6: Pattern Crosswalked due to defect with PMM including support lines prior and after proc code effective dates. | C6: 1
A7: 27 | B7: Pattern Crosswalked due to defect with PMM including support lines prior and after proc code effective dates. | C7: 1
A8: 28 | B8: Pattern Crosswalked due to defect with PMM including support lines prior and after proc code effective dates. | C8: 1
A9: 29 | B9: Pattern Crosswalked due to defect with PMM including support lines prior and after proc code effective dates. | C9: 1
A10: 30 | B10: Pattern Crosswalked due to defect with PMM including support lines prior and after proc code effective dates. | C10: 1
A11: 32 | B11: Pattern Crosswalked due to defect with PMM including support lines prior and after proc code effective dates. | C11: 1
A12: 33 | B12: Pattern Crosswalked due to defect with PMM including support lines prior and after proc code effective dates. | C12: 1
A13: 36 | B13: Pattern Crosswalked due to defect with PMM including support lines prior and after proc code effective dates. | C13: 1
... A68: 373 | B68: Pattern Crosswalked due to defect with PMM including support lines prior and after proc code effective dates. | C68: 1
A69: C5 | B69: Pattern Crosswalked due to defect with PMM including support lines prior and after proc code effective dates. | C69: 1
A70: 285 | B70: Revenue Codes with a leading 0 should accumulate with the same revenue code without the 0. Therefore, group pattern is required for rev code policies. | C70: 1
A71: 360 | B71: Revenue Codes with a leading 0 should accumulate with the same revenue code without the 0. Therefore, group pattern is required for rev code policies. | C71: 1
A72: 361 | B72: Revenue Codes with a leading 0 should accumulate with the same revenue code without the 0. Therefore, group pattern is required for rev code policies. | C72: 1
A73: 362 | B73: Revenue Codes with a leading 0 should accumulate with the same revenue code without the 0. Therefore, group pattern is required for rev code policies. | C73: 1
A74: 400 | B74: Revenue Codes with a leading 0 should accumulate with the same revenue code without the 0. Therefore, group pattern is required for rev code policies. | C74: 1
A75: 485 | B75: Removed TOS criteria, as of 12/27/2022, clients are not passing us TOS information | C75: 2
A76: 486 | B76: Removed TOS criteria, as of 12/27/2022, clients are not passing us TOS information | C76: 2
A77: 487 | B77: Removed TOS criteria, as of 12/27/2022, clients are not passing us TOS information | C77: 2
A78: 488 | B78: Removed TOS criteria, as of 12/27/2022, clients are not passing us TOS information | C78: 2
A79: 489 | B79: Removed TOS criteria, as of 12/27/2022, clients are not passing us TOS information | C79: 2
A80: 490 | B80: Removed TOS criteria, as of 12/27/2022, clients are not passing us TOS information | C80: 2
A81: 491 | B81: Removed TOS criteria, as of 12/27/2022, clients are not passing us TOS information | C81: 2
... A158: 386 | B158: This is a dupe of 289 | C158: 1

Sheet DEFAULT_Combo Index Numbers
A1: Combo Index Number | B1: Policy Name | C1: Client | D1: Index Number Status

Sheet STM_Combo Index Numbers
A1: Combo Index Number | B1: State | C1: Index Number Status | D1: Policy Name
A2: 1 | B2: MA | C2: Submitted | D2: DEF_MA_CT_DME_POS_S_A | F2: Index Number Status | G2: Status Defined
A3: 2 | B3: CA | C3: Submitted | D3: DEF_CA_EYESCODI_1, DEF_CA_EYESCODI_2, DEF_CA_EYESCODI_3 | F3: Submitted | G3: Used by Peer Reviewers to denote combo policies have been submitted for Quality Assurance (QA)
A4: 3 | B4: NJ | C4: Submitted | D4: DEF_NJ_NL_MAT_1, DEF_NJ_NL_MAT_2 | F4: In Progress | G4: Used by developers to denote the Combo Index Number has been taken and should not be used by other developers. Peer Reviewers are to change the status from "In Progress" to "Submitted."
A5: 4 | B5: CA | C5: Submitted | D5: DEF_CA_HCPCS_J1939_1, DEF_CA_HCPCS_J1939_2
A6: 5 | B6: CA | C6: Submitted | D6: DEF_CA_CHEM_EPKINLY, DEF_CA_CHEM_EPKINLY_2
A7: 6 | B7: CA | C7: Submitted | D7: DEF_CA_INJ_FLUPHE_1, DEF_CA_INJ_FLUPHE_2, DEF_CA_INJ_FLUPHE_3
A8: 7 | B8: CA | C8: Submitted | D8: DEF_CA_HCPCS_BR_IMG_1 , DEF_CA_HCPCS_BR_IMG_2
A9: 8 | B9: CA | C9: Submitted | D9: DEF_CA_BL_Q4UPD_FLOT_1, DEF_CA_BL_Q4UPD_FLOT_2
A10: 9 | B10: CA | C10: Submitted | D10: DEF_CA_INJ_BRIX_1, DEF_CA_INJ_BRIX_2, DEF_CA_INJ_BRIX_3
A11: 10 | B11: CA | C11: Submitted | D11: DEF_CA_SARS_COV_1, DEF_CA_SARS_COV_2, DEF_CA_SARS_COV_3
A12: 11 | B12: LA | C12: Submitted | D12: DEF_LA_FS_PROFSER_SATCESS_1, DEF_LA_FS_PROFSER_SATCESS_2
A13: 12 | B13: CA | C13: Submitted | D13: DEF_CA_EYE_ULTRASOUND_1, DEF_CA_EYE_ULTRASOUND_2
A14: 13 | B14: TX | C14: In Progress | D14: DEF_TX_MH_OPDRG_BESPO_1, DEF_TX_MH_OPDRG_BESPO_2
A15: 14 | B15: CA | C15: Submitted | D15: DEF_CA_CARDIO_TEE_1, DEF_CA_CARDIO_TEE_4, DEF_CA_CARDIO_TEE_5, DEF_CA_CARDIO_TEE_6,DEF_CA_CARDIO_TEE_7,DEF_CA_CARDIO_TEE_8,DEF_CA_CARDIO_TEE_9
A16: 15 | B16: GA | C16: Submitted | D16: DEF_GA_FS_ORTH_PROS_FRQ_B_1, DEF_GA_FS_ORTH_PROS_FRQ_B_2
... A155: 157 | B155: CA | C155: In Progress | D155: DEF_CA_MH_PHYS_HCPCS21_1,DEF_CA_MH_PHYS_HCPCS21_2A,DEF_CA_MH_PHYS_HCPCS21_2B
A156: 158
A157: 159 | B157: CA | C157: In Progress | D157: DEF_CA_HCPCS_MRIGUIDE_1, DEF_CA_HCPCS_MRIGUIDE_2
A158: 160 | B158: CA | C158: In Progress | D158: DEF_CA_HCPCS_PROSTCAMAP_1, DEF_CA_HCPCS_PROSTCAMAP_2
A159: 161 | B159: CA | C159: Submitted | D159: DEF_CA_MH_PHYS_HCPCS21_1, DEF_CA_MH_PHYS_HCPCS21_2A, DEF_CA_MH_PHYS_HCPCS21_2B
A160: 162 | B160: KS | C160: In Progress | D160: DEF_KS_MH_PROF_POLY_SS_PRV_1, DEF_KS_MH_PROF_POLY_SS_PRV_2, DEF_KS_MH_PROF_POLY_SS_PRV_3, DEF_KS_MH_PROF_POLY_SS_PRV_4
A161: 163 | B161: CA | C161: In Progress | D161: DEF_CA_BL_Q4UPD_HIST_1; DEF_CA_BL_Q4UPD_HIST_2
A162: 164 | B162: MA | C162: In Progress | D162: DEF_MA_CT_DME_FREQ_S_R_1, DEF_MA_CT_DME_FREQ_S_R_2, DEF_MA_CT_DME_FREQ_S_R_3, DEF_MA_CT_DME_FREQ_S_R_4, DEF_MA_CT_DME_FREQ_S_R_5, DEF_MA_CT_DME_FREQ_S_R_6, DEF_MA_CT_DME_FREQ_S_R_7, DEF_MA_CT_DME_FREQ_S_R_8, DEF_MA_CT_DME_FREQ_S_R_9, DEF_MA_CT_DME_FREQ_S_R10, DEF_MA_CT_DME_FREQ_S_R11, DEF_MA_CT_DME_FREQ_S_R12, DEF_MA_CT_DME_FREQ_S_R13, DEF_MA_CT_DME_FREQ_S_R14, DEF_MA_CT_DME_FREQ_S_R15, DEF_MA_CT_DME_FREQ_S_R16, DEF_MA_CT_DME_FREQ_S_R17, DEF_MA_CT_DME_FREQ_S_R18, DEF_MA_CT_DME_MOD_S_A, DEF_MA_CT_DME_POS_S_F
A163: 165 | B163: MA | C163: In Progress | D163: DEF_MA_CT_OXY_FREQ_S_G, DEF_MA_CT_OXY_MOD_S_D, DEF_MA_CT_OXY_FREQ_S_E, DEF_MA_CT_OXY_FREQ_S_D, DEF_MA_CT_OXY_POS_S_A, DEF_MA_CT_OXY_POS_S_C, DEF_MA_CT_OXY_FREQ_S_H, DEF_MA_CT_OXY_FREQ_S_H2, DEF_MA_CT_OXY_FREQ_S_D2
A164: 166 | B164: MA | C164: In Progress | D164: DEF_MA_CT_OXY_FREQ_S_J, DEF_MA_CT_OXY_FREQ_S_J2, DEF_MA_CT_OXY_MOD_S_G2, DEF_MA_CT_OXY_POS_S_B
A165: 167 | B165: KS | C165: In Progress | D165: DEF_KS_MH_PROF_POLY_SS_FRQ_1, DEF_KS_MH_PROF_POLY_SS_FRQ_2
A166: 168 | B166: AZ | C166: Submitted | D166: DEF_AZ_NL_BYOOVIZ; DEF_AZ_NL_BYOOVIZ_2
A167: 169 | B167: AZ | D167: DEF_AZ_MH_UDS_FREQ_A1, DEF_AZ_MH_UDS_FREQ_A2
A168: 170 | B168: AZ | D168: DEF_AZ_MH_UDS_FREQ_B1,DEF_AZ_MH_UDS_FREQ_B2
A169: 171 | B169: AZ | D169: DEF_AZ_MH_UDS_FREQ_C1, DEF_AZ_MH_UDS_FREQ_C2
A170: 172 | B170: AZ | D170: DEF_AZ_BHS_COUNS_1, DEF_AZ_BHS_COUNS_2
A171: 173 | B171: TX | D171: DEF_TX_INJ_ELEVIDYS_1A, DEF_TX_INJ_ELEVIDYS_2, DEF_TX_INJ_ELEVIDYS_3
A172: 174 | B172: AZ | C172: In Progress | D172: DEF_AZ_NL_MTRNL_DEP_1,DEF_AZ_NL_MTRNL_DEP_2
A173: 175 | B173: AZ | C173: In Progress | D173: DEF_AZ_BHS_MHPS_1, DEF_AZ_BHS_MHPS_2
A174: 176 | B174: AZ | C174: In Progress | D174: DEF_AZ_BHS_RESPITE_SVC_1, DEF_AZ_BHS_RESPITE_SVC_1
A175: 177 | B175: AZ | C175: Submitted | D175: DEF_AZ_NL_EK_MEDROXY_1, DEF_AZ_NL_EK_MEDROXY_2
A176: 178 | B176: AZ | D176: DEF_KS_BL_TPCL_FLRDE_1, DEF_KS_BL_TPCL_FLRDE_2
A177: 179 | B177: KS | D177: DEF_KS_HOSP_SSPSG_1, DEF_KS_HOSP_SSPSG_2, DEF_KS_HOSP_SSPSG_3, DEF_KS_HOSP_SSPSG_4
A178: 180 | B178: KS | D178: DEF_KS_BL_TFLOURIDE_1, DEF_KS_BL_TFLOURIDE_2
...

Sheet Sheet1

Sheet DEFAULT_GROUPS
A1: Edit Type | B1: Aetna | C1: HCSC | D1: Elevance
A2: SINGLE_LINE | B2: CXT_BASE_1_486 | C2: CXT_BASE_1_491 | D2: CXT_BASE_1_496
A3: WITH_SUPPORT | B3: CXT_BASE_1_487 | C3: CXT_BASE_1_492 | D3: CXT_BASE_1_497
A4: WITHOUT_SUPPORT | B4: CXT_BASE_1_488 | C4: CXT_BASE_1_493 | D4: CXT_BASE_1_498
A5: FREQ | B5: CXT_BASE_1_489 | C5: CXT_BASE_1_494 | D5: CXT_BASE_1_499
A6: Multiple Edit Type Combination | B6: CXT_BASE_1_490 | C6: CXT_BASE_1_495 | D6: CXT_BASE_1_500

Sheet STM_GROUPS
A1: *Edit Type by State
A2: Edit Type | B2: AZ Groups | C2: CA Groups | D2: FL Groups | E2: GA Groups | F2: IA | G2: ID | H2: IL Groups | I2: KS Groups | J2: KY Groups | K2: LA Groups | L2: MA Groups | M2: MD Groups | N2: MI Groups | O2: MS Groups | P2: NE Groups | Q2: NJ Groups | R2: NM Groups | S2: NV Groups | T2: NY Groups | U2: OH Groups | V2: PA Groups | W2: SC Groups | X2: TX Groups | Y2: UT Groups | Z2: VA Groups | AA2: WA Groups | AB2: WI Groups | AC2: WVA Groups | AD2: HISTORY_DEFINITION | AE2: FIRING ORDER AMONGST OTHER STATE GROUPS | AF2: USE_EDIT_LINE_AS_SUPPORT, USE_ADD_LINE_AS_SUPPORT
A3: SINGLE_LINE | B3: CXT_BASE_1_255 | C3: CXT_BASE_1_015 | D3: CXT_BASE_1_275 | E3: CXT_BASE_1_200 | F3: CXT_BASE_1_471 | G3: CXT_BASE_1_461 | H3: CXT_BASE_1_235 | I3: CXT_BASE_1_230 | J3: CXT_BASE_1_260 | K3: CXT_BASE_1_028 | L3: CXT_BASE_1_225 | M3: CXT_BASE_1_265 | N3: CXT_BASE_1_270 | O3: CXT_BASE_1_215 | P3: CXT_BASE_1_290 | Q3: CXT_BASE_1_220 | R3: CXT_BASE_1_476 | S3: CXT_BASE_1_295 | T3: CXT_BASE_1_011 | U3: CXT_BASE_1_250 | V3: CXT_BASE_1_280 | W3: CXT_BASE_1_210 | X3: CXT_BASE_1_012 | Y3: CXT_BASE_1_285 | Z3: CXT_BASE_1_240 | AA3: CXT_BASE_1_205 | AB3: CXT_BASE_1_466 | AC3: CXT_BASE_1_245 | AD3: SINGLE_LINE | AE3: 1 | AF3: NULL
A4: WITH_SUPPORT | B4: CXT_BASE_1_256 | C4: CXT_BASE_1_017 | D4: CXT_BASE_1_276 | E4: CXT_BASE_1_201 | F4: CXT_BASE_1_472 | G4: CXT_BASE_1_462 | H4: CXT_BASE_1_236 | I4: CXT_BASE_1_231 | J4: CXT_BASE_1_261 | K4: CXT_BASE_1_029 | L4: CXT_BASE_1_226 | M4: CXT_BASE_1_266 | N4: CXT_BASE_1_271 | O4: CXT_BASE_1_216 | P4: CXT_BASE_1_291 | Q4: CXT_BASE_1_221 | R4: CXT_BASE_1_477 | S4: CXT_BASE_1_296 | T4: CXT_BASE_1_013 | U4: CXT_BASE_1_251 | V4: CXT_BASE_1_281 | W4: CXT_BASE_1_211 | X4: CXT_BASE_1_020 | Y4: CXT_BASE_1_286 | Z4: CXT_BASE_1_241 | AA4: CXT_BASE_1_206 | AB4: CXT_BASE_1_467 | AC4: CXT_BASE_1_246 | AD4: ALL_AVAILABLE | AE4: 2 | AF4: NULL (ON_BOTH will cause issues with cyclical denials allowing no lines to be paid when freq is exceeded)
A5: WITHOUT_SUPPORT | B5: CXT_BASE_1_257 | C5: CXT_BASE_1_018 | D5: CXT_BASE_1_277 | E5: CXT_BASE_1_202 | F5: CXT_BASE_1_473 | G5: CXT_BASE_1_463 | H5: CXT_BASE_1_237 | I5: CXT_BASE_1_232 | J5: CXT_BASE_1_262 | K5: CXT_BASE_1_030 | L5: CXT_BASE_1_227 | M5: CXT_BASE_1_267 | N5: CXT_BASE_1_272 | O5: CXT_BASE_1_217 | P5: CXT_BASE_1_292 | Q5: CXT_BASE_1_222 | R5: CXT_BASE_1_478 | S5: CXT_BASE_1_297 | T5: CXT_BASE_1_014 | U5: CXT_BASE_1_252 | V5: CXT_BASE_1_282 | W5: CXT_BASE_1_212 | X5: CXT_BASE_1_024 | Y5: CXT_BASE_1_287 | Z5: CXT_BASE_1_242 | AA5: CXT_BASE_1_207 | AB5: CXT_BASE_1_468 | AC5: CXT_BASE_1_247 | AD5: ALL_AVAILABLE | AE5: 3 | AF5: NULL (ON_BOTH will cause issues with cyclical denials allowing no lines to be paid when freq is exceeded)
A6: FREQ | B6: CXT_BASE_1_258 | C6: CXT_BASE_1_016 | D6: CXT_BASE_1_278 | E6: CXT_BASE_1_203 | F6: CXT_BASE_1_474 | G6: CXT_BASE_1_464 | H6: CXT_BASE_1_238 | I6: CXT_BASE_1_233 | J6: CXT_BASE_1_263 | K6: CXT_BASE_1_034 | L6: CXT_BASE_1_228 | M6: CXT_BASE_1_268 | N6: CXT_BASE_1_273 | O6: CXT_BASE_1_218 | P6: CXT_BASE_1_293 | Q6: CXT_BASE_1_223 | R6: CXT_BASE_1_479 | S6: CXT_BASE_1_298 | T6: CXT_BASE_1_009 | U6: CXT_BASE_1_253 | V6: CXT_BASE_1_283 | W6: CXT_BASE_1_213 | X6: CXT_BASE_1_019 | Y6: CXT_BASE_1_288 | Z6: CXT_BASE_1_243 | AA6: CXT_BASE_1_208 | AB6: CXT_BASE_1_469 | AC6: CXT_BASE_1_248 | AD6: ALL_AVAILABLE | AE6: 4 | AF6: NULL (ON_BOTH will cause issues with cyclical denials allowing no lines to be paid when freq is exceeded)
A7: Multiple Edit Type Combination | B7: CXT_BASE_1_259 | C7: CXT_BASE_1_025 | D7: CXT_BASE_1_279 | E7: CXT_BASE_1_204 | F7: CXT_BASE_1_475 | G7: CXT_BASE_1_465 | H7: CXT_BASE_1_239 | I7: CXT_BASE_1_234 | J7: CXT_BASE_1_264 | K7: CXT_BASE_1_035 | L7: CXT_BASE_1_229 | M7: CXT_BASE_1_269 | N7: CXT_BASE_1_274 | O7: CXT_BASE_1_219 | P7: CXT_BASE_1_294 | Q7: CXT_BASE_1_224 | R7: CXT_BASE_1_480 | S7: CXT_BASE_1_299 | T7: CXT_BASE_1_026 | U7: CXT_BASE_1_254 | V7: CXT_BASE_1_284 | W7: CXT_BASE_1_214 | X7: CXT_BASE_1_027 | Y7: CXT_BASE_1_289 | Z7: CXT_BASE_1_244 | AA7: CXT_BASE_1_209 | AB7: CXT_BASE_1_470 | AC7: CXT_BASE_1_249 | AD7: ALL_AVAILABLE | AE7: 5 | AF7: OFF
A9: *State by Edit Type
A10: State | B10: SINGLE_LINE | C10: WITH_SUPPORT | D10: WITHOUT_SUPPORT | E10: FREQ | F10: Multiple Edit Type Combination
A11: AZ | B11: CXT_BASE_1_255 | C11: CXT_BASE_1_256 | D11: CXT_BASE_1_257 | E11: CXT_BASE_1_258 | F11: CXT_BASE_1_259
A12: CA | B12: CXT_BASE_1_015 | C12: CXT_BASE_1_017 | D12: CXT_BASE_1_018 | E12: CXT_BASE_1_016 | F12: CXT_BASE_1_025
A13: FL | B13: CXT_BASE_1_275 | C13: CXT_BASE_1_276 | D13: CXT_BASE_1_277 | E13: CXT_BASE_1_278 | F13: CXT_BASE_1_279
A14: GA | B14: CXT_BASE_1_200 | C14: CXT_BASE_1_201 | D14: CXT_BASE_1_202 | E14: CXT_BASE_1_203 | F14: CXT_BASE_1_204
A15: IA | B15: CXT_BASE_1_471 | C15: CXT_BASE_1_472 | D15: CXT_BASE_1_473 | E15: CXT_BASE_1_474 | F15: CXT_BASE_1_475
A16: ID | B16: CXT_BASE_1_461 | C16: CXT_BASE_1_462 | D16: CXT_BASE_1_463 | E16: CXT_BASE_1_464 | F16: CXT_BASE_1_465
A17: IL | B17: CXT_BASE_1_235 | C17: CXT_BASE_1_236 | D17: CXT_BASE_1_237 | E17: CXT_BASE_1_238 | F17: CXT_BASE_1_239
A18: KS | B18: CXT_BASE_1_230 | C18: CXT_BASE_1_231 | D18: CXT_BASE_1_232 | E18: CXT_BASE_1_233 | F18: CXT_BASE_1_234
A19: KY | B19: CXT_BASE_1_260 | C19: CXT_BASE_1_261 | D19: CXT_BASE_1_262 | E19: CXT_BASE_1_263 | F19: CXT_BASE_1_264
A20: LA | B20: CXT_BASE_1_028 | C20: CXT_BASE_1_029 | D20: CXT_BASE_1_030 | E20: CXT_BASE_1_034 | F20: CXT_BASE_1_035
A21: MA | B21: CXT_BASE_1_225 | C21: CXT_BASE_1_226 | D21: CXT_BASE_1_227 | E21: CXT_BASE_1_228 | F21: CXT_BASE_1_229
... A39: HISTORY_DEFINITION | B39: SINGLE_LINE | C39: ALL_AVAILABLE | D39: ALL_AVAILABLE | E39: ALL_AVAILABLE | F39: ALL_AVAILABLE
A40: FIRING ORDER AMONGST OTHER STATE GROUPS | B40: 1 | C40: 2 | D40: 3 | E40: 4 | F40: 5

Sheet AGE_DESIGNATION
A1: AGE_DESIGNATION | B1: DAYS_OR_YEARS | C1: GREATER_THAN_OR_LESS_THAN | D1: AGE_1 | E1: GREATER_THAN_OR_LESS_THAN | F1: AGE_2
A2: AGE_12M | B2: DAYS | C2: > | D2: 1 | E2: < | F2: 366
A3: AGE_19_THRU_64 | B3: YEARS | C3: > | D3: 18 | E3: < | F3: 65
A4: AGE_BT10_18Y | B4: YEARS | C4: > | D4: 9 | E4: < | F4: 19
A5: AGE_BT10_55Y | B5: YEARS | C5: > | D5: 9 | E5: < | F5: 56
A6: AGE_BT10_59Y | B6: YEARS | C6: > | D6: 9 | E6: < | F6: 60
A7: AGE_BT10_60Y | B7: YEARS | C7: > | D7: 9 | E7: < | F7: 61
A8: AGE_BT11_20Y | B8: YEARS | C8: > | D8: 10 | E8: < | F8: 21
A9: AGE_BT12_17Y | B9: YEARS | C9: > | D9: 11 | E9: < | F9: 18
A10: AGE_BT16_60Y | B10: YEARS | C10: > | D10: 15 | E10: < | F10: 61
A11: AGE_BT181_1459D | B11: DAYS | C11: > | D11: 180 | E11: < | F11: 1460
A12: AGE_BT18_20Y | B12: YEARS | C12: > | D12: 17 | E12: < | F12: 21
A13: AGE_BT18_39Y | B13: YEARS | C13: > | D13: 17 | E13: < | F13: 40
... A15: AGE_BT18_65Y | B15: YEARS | C15: > | D15: 18 | E15: < | F15: 65
A16: AGE_BT19_20Y | B16: YEARS | C16: > | D16: 18 | E16: < | F16: 21 | M16: 40
A17: AGE_BT19_59Y | B17: YEARS | C17: > | D17: 18 | E17: < | F17: 60
A18: AGE_BT1_2Y | B18: DAYS | C18: > | D18: 365 | E18: < | F18: 730
A19: AGE_BT21_59Y | B19: YEARS | C19: > | D19: 20 | E19: < | F19: 60
A20: AGE_BT21_64Y | B20: YEARS | C20: > | D20: 20 | E20: < | F20: 65
A21: AGE_BT21_99Y | B21: YEARS | C21: > | D21: 20 | E21: < | F21: 100
A22: AGE_BT22_64Y | B22: YEARS | C22: > | D22: 21 | E22: < | F22: 65
A23: AGE_BT2_20Y | B23: YEARS | C23: > | D23: 1 | E23: < | F23: 21
A24: AGE_BT2_21Y | B24: DAYS | C24: > | D24: 730 | E24: < | F24: 7670
A25: AGE_BT30_2556D | B25: DAYS | C25: > | D25: 30 | E25: < | F25: 2556
A26: AGE_BT30_719D | B26: DAYS | C26: < | D26: 29 | E26: > | F26: 720
A27: AGE_BT35_39Y | B27: YEARS | C27: > | D27: 34 | E27: < | F27: 40
A28: AGE_BT365_7300D | B28: DAYS | C28: > | D28: 365 | E28: < | F28: 7300
... A44: AGE_BTW6_11Y | B44: YEARS | C44: > | D44: 5 | E44: < | F44: 12
A45: AGE_GT100Y | B45: YEARS | C45: > | D45: 100
A46: AGE_GT1024M | B46: DAYS | C46: > | D46: 31145
A47: AGE_GT10Y | B47: YEARS | C47: > | D47: 10
A48: AGE_GT11M | B48: DAYS | C48: > | D48: 330
A49: AGE_GT11Y | B49: YEARS | C49: > | D49: 11
A50: AGE_GT120Y | B50: YEARS | C50: > | D50: 120
A51: AGE_GT125Y | B51: YEARS | C51: > | D51: 125
A52: AGE_GT12Y | B52: YEARS | C52: > | D52: 12
A53: AGE_GT130Y | B53: YEARS | C53: > | D53: 130
A54: AGE_GT132M | B54: DAYS | C54: > | D54: 4015
A55: AGE_GT13Y | B55: YEARS | C55: > | D55: 13
A56: AGE_GT143M | B56: DAYS | C56: > | D56: 4345
...

Sheet Pattern CROSSWALK
A1: *If policy is attached to a combination pattern, please reference the individual pattern number to obtain crosswalk assignment
A2: Impacted Pattern | B2: XWALK | C2: EDIT TYPE
A3: 13 | B3: 250 | C3: FREQ
A4: 16 | B4: * | C4: COMBO
A5: 17 | B5: * | C5: COMBO
A6: 18 | B6: * | C6: COMBO
A7: 25 | B7: 405 | C7: FREQ
A8: 27 | B8: 389 | C8: FREQ
A9: 28 | B9: * | C9: COMBO
A10: 29 | B10: 250 | C10: FREQ
A11: 30 | B11: * | C11: COMBO
A12: 32 | B12: 289 | C12: FREQ
A13: 33 | B13: * | C13: COMBO
A14: 36 | B14: * | C14: COMBO
A15: 45 | B15: * | C15: COMBO
A16: 54 | B16: 390 | C16: FREQ
A17: 55 | B17: * | C17: COMBO
A18: 57 | B18: * | C18: COMBO
A19: 59 | B19: * | C19: COMBO
A20: 60 | B20: * | C20: COMBO
A21: 61 | B21: * | C21: COMBO
A22: 62 | B22: 391 | C22: FREQ
A23: 63 | B23: 391 | C23: FREQ
A24: 65 | B24: * | C24: COMBO
A25: 66 | B25: * | C25: COMBO
A26: 68 | B26: 392 | C26: FREQ
A27: 80 | B27: 393 | C27: FREQ
A28: 94 | B28: 385 | C28: FREQ
A29: 97 | B29: 386 | C29: FREQ
A30: 108 | B30: 405 | C30: FREQ
A31: 130 | B31: 389 | C31: FREQ
A32: 134 | B32: 250 | C32: FREQ
A33: 142 | B33: 394 | C33: FREQ
A34: 143 | B34: 401 | C34: FREQ
A35: 144 | B35: 387 | C35: FREQ
A36: 162 | B36: 392 | C36: FREQ
A37: 165 | B37: 395 | C37: FREQ
... A69: 373 | B69: 404 | C69: FREQ
A70: C5 | B70: * | C70: COMBO
A71: *If policy is attached to a combination pattern, look at individual pattern number to obtain crosswalk assignment

Sheet Naming Convention - Nested Cats
A1: Category Suffix Suggestions | B1: Category Structure
A2: Diagnosis | B2: (PMM_TYPE)_&CORE_DIAG
A3: Proc Code | B3: (PMM_TYPE)_&CORE_PROC
A4: Proc Code Category (WITH/WITHOUT) | B4: (PMM_TYPE)_&CORE_DENY_PROC
A5: Proc Code Category (WITH/WITHOUT) | B5: (PMM_TYPE)_&CORE_SUPPORT_PROC
A6: Place of Service | B6: (PMM_TYPE)_&CORE_POS
A7: Provider Specialty | B7: (PMM_TYPE)_&CORE_PROV_SPEC
A8: Provider Type | B8: (PMM_TYPE)_&CORE_PROV_TYPE
A9: Modifier | B9: (PMM_TYPE)_&CORE_MOD
A10: Revenue Code | B10: (PMM_TYPE)_&CORE_REV
A11: Bill Type | B11: (PMM_TYPE)_&CORE_BILL_TYPE
A12: Gender | B12: (PMM_TYPE)_&CORE_GENDER
... A18: Diagnosis ICD 10 | B18: (PMM_TYPE)_&CORE_PROC_CODE

Sheet Claim Types
A1: Number | B1: Client Policy Claim Type | C1: DataField1 | D1: Category name (Lookup2) | E1: Datafield2 | F1: Category2 | G1: DataField3 (Lookup5) | H1: Category3 name (Lookup6) | I1: DataField4 (Lookup7) | J1: Category4 name
A2: (Key 1) | B2: (Key2) | C2: (Lookup1) | E2: (Lookup3 | F2: name | J2: (Lookup8)
F3: (Lookup4)
A4: 1 | B4: PROF | C4: Claim_FacilityFlag | D4: C;VAL;!=;Y | E4: Claim_BillType | F4: C;VAL;IS_NULL
A5: 2 | B5: OUTPAT_FAC | C5: Claim_FacilityFlag | D5: C;VAL;=;Y | E5: Claim_BillType | F5: C;CAT;IN_DICT;OUTPAT_BILL_TYPE
A6: 3 | B6: INPAT_FAC | C6: Claim_FacilityFlag | D6: C;VAL;=;Y | E6: Claim_BillType | F6: C;CAT;IN_DICT;INPAT_BILL_TYPE
A7: 4 | B7: ALL_FAC | C7: Claim_FacilityFlag | D7: C;VAL;=;Y
A8: 5 | B8: OP_PROF | C8: Claim_FacilityFlag | D8: C;VAL;!=;Y | E8: Line_PlaceOfService | F8: C;CAT;IN_DICT;OUTPAT_POS
A9: 6 | B9: IP_PROF | C9: Claim_FacilityFlag | D9: C;VAL;!=;Y | E9: Line_PlaceOfService | F9: C;CAT;IN_DICT;INPAT_POS

Sheet MASTER
A1: Policy Element | B1: Description | C1: SINGLE_LINE | D1: WITH_SUPPORT | E1: WITHOUT_SUPPORT | F1: FREQ | G1: Allowed Options (if applicable)
A2: POLICY_NAME | B2: AKA Policy Acronym. MUST begin with "DEF_". 30 is the maximum number of characters for a policy name – including underscores. | C2: Required | D2: Required | E2: Required | F2: Required | G2: Variable, must begin with "DEF_", and must not exceed 30 characters, no spaces allowed.
A3: POLICY_DESCRIPTION | B3: "Long name" of policy as opposed to policy acronym. | C3: Required | D3: Required | E3: Required | F3: Required | G3: Variable according to policy.
A4: EXPECTED_AUDITING_OUTCOME | B4: Describes the purpose of the policy. It is suggesed to begin with "This policy will Deny … | C4: Required | D4: Required | E4: Required | F4: Required | G4: Variable according to policy.
A5: EDIT_VARIATION | B5: 1 Edit Variation is Required for each policy. | C5: Required | D5: Required | E5: Required | F5: Required | G5: Valid Entries: •SINGLE_LINE •WITH_SUPPORT •WITHOUT_SUPPORT •FREQ
A6: POLICY_EFFECTIVE_DATE | B6: Effective From Date of the Policy | C6: Required | D6: Required | E6: Required | F6: Required | G6: Must be in MM/DD/YYYY Format
A7: CURRENT CLAIM_TYPE | B7: Used to define the applicable claim types at the Policy Level for the Current (deny) Line. | C7: Required (if no claim type is required please indicate "NULL" in field | D7: Required (if no claim type is required please indicate "N/A" in field. | E7: Required (if no claim type is required please indicate "N/A" in field. | F7: Required (if no claim type is required please indicate "N/A" in field. | G7: Valid Entries (can add if needed): •PROF (Facility Flag not = Y and Bill Type field blank) •OUTPAT_FAC (Outpatient Bill Types) •INPAT_FAC (Inpatient Bill Types) •ALL_FAC (IP + OP) •OP _PROF •IP _PROF •NULL (equates to ALL Claim Types)
A8: SUPPORT CLAIM_TYPE | B8: Used to define the applicable claim types at the Policy Level for the Support Line. Typically for multiple line edits the support claim type equals the current claim type. | C8: N/A | D8: Required (if no claim type is required please indicate "N/A" in field. | E8: Required (if no claim type is required please indicate "N/A" in field. | F8: Required (if no claim type is required please indicate "N/A" in field. | G8: Valid Entries (can add if needed): •PROF (Facility Flag not = Y and Bill Type field blank) •OUTPAT_FAC (Outpatient Bill Types) •INPAT_FAC (Inpatient Bill Types) •ALL_FAC (IP + OP) •OP _PROF •IP _PROF •NULL (equates to ALL Claim Types)
A9: PROVIDER_MATCHING | B9: Optional for Multiple Line edits, Value can contain 1 or multiple Provider matching variation separated by a semicolon. NULL indicates edit goes across all providers | C9: N/A | D9: Required (if no provider matching is required please indicate "N/A" in field | E9: Required (if no provider matching is required please indicate "N/A" in field | F9: Required (if no provider matching is required please indicate "N/A" in field | G9: Valid entries: if not "NULL", valid entries are on PROVIDER MATCHING OPTIONS Tab in Column A (Keyword Variation), if applicable for edit type can be "NULL", or populated with 1 or more variations deparated by semi-colon without any spaces
